Workbook

Sheet Planilha1
B1: CNPJ2 | C1: CEG | D1: Usina
A2: 121 | B2: =VLOOKUP($C2,Planilha2!$B:$E,4,FALSE) -> 10618009000114 | C2: 31598 | D2: ADOPOPINHAK
A3: 14056 | B3: 23.865.997/0001-48 | C3: 29555 | D3: AREMBEPE
A4: 20295 | B4: =VLOOKUP($C4,Planilha2!$B:$E,4,FALSE) -> 330001670001E5 | C4: 1096 | D4: AURELIANOCHAVES(ANTIGAIBIRITE)
A5: 2190 | B5: =VLOOKUP($C5,Planilha2!$B:$E,4,FALSE) -> 07799995000141 | C5: 29453 | D5: BAGUARI-COTABAGUARII
A6: 754 | B6: =VLOOKUP($C6,Planilha2!$B:$E,4,FALSE) -> 07799995000141 | C6: 29453 | D6: BAGUARI-COTACEMIG
A7: 741 | B7: =VLOOKUP($C7,Planilha2!$B:$E,4,FALSE) -> 07799995000141 | C7: 29453 | D7: BAGUARI-COTAFURNAS
A8: 2703 | B8: 23.865.997/0001-48 | C8: 28615 | D8: BAHIAI
A9: 310134 | B9: =VLOOKUP($C9,Planilha2!$B:$E,4,FALSE) -> 330001670001E5 | C9: 27952 | D9: BARBOSALIMASOBRINHO
A10: 113106 | B10: =VLOOKUP($C10,Planilha2!$B:$E,4,FALSE) -> 330001670001E5 | C10: 27952 | D10: BARBOSALIMASOBRINHO(ANTIGAELETROBOLT)
A11: 230 | B11: 12.300.288/0001-07 | C11: 30354 | D11: BELOMONTE2
A12: 646 | B12: =VLOOKUP($C12,Planilha2!$B:$E,4,FALSE) -> 23857764000101 | C12: 33467 | D12: BOLTBAH
A13: 456 | B13: 23.865.997/0001-48 | C13: 29554 | D13: CAMACARIMURICYI
A14: 454 | B14: 23.865.997/0001-48 | C14: 29555 | D14: CAMACARIPOLODEAPOIOI
A15: 2338 | B15: =VLOOKUP($C15,Planilha2!$B:$E,4,FALSE) -> 02016507000169 | C15: 29767 | D15: CANDIOTAIII(FASECDAUSINATERMELETRICAPRESIDENTEMEDICI)
A16: 476 | B16: =VLOOKUP($C16,Planilha2!$B:$E,4,FALSE) -> 15394399000100 | C16: 30897 | D16: CARCARA2
A17: 3266 | B17: =VLOOKUP($C17,Planilha2!$B:$E,4,FALSE) -> 330001670001E5 | C17: 27263 | D17: CELSOFURTADO
A18: 115991 | B18: =VLOOKUP($C18,Planilha2!$B:$E,4,FALSE) -> 330001670001E5 | C18: 27263 | D18: CELSOFURTADO(ANTIGATERMOBAHIAFASEI)
A19: 531 | B19: 76.321.496/0001-67 | C19: 27978 | D19: CISFRAMA
A20: 633 | B20: =VLOOKUP($C20,Planilha2!$B:$E,4,FALSE) -> 330001670001E5 | C20: 28014 | D20: CUBATAO
A21: 317 | B21: =VLOOKUP($C21,Planilha2!$B:$E,4,FALSE) -> 23598517000120 | C21: 33682 | D21: DELTA3I
A22: 383 | B22: =VLOOKUP($C22,Planilha2!$B:$E,4,FALSE) -> 23598858000103 | C22: 33683 | D22: DELTA3II
A23: 933 | B23: =VLOOKUP($C23,Planilha2!$B:$E,4,FALSE) -> 23598847000115 | C23: 33684 | D23: DELTA3III
A24: 2361 | B24: =VLOOKUP($C24,Planilha2!$B:$E,4,FALSE) -> 23598842000192 | C24: 33685 | D24: DELTA3IV
A25: 627 | B25: =VLOOKUP($C25,Planilha2!$B:$E,4,FALSE) -> 23598829000133 | C25: 33675 | D25: DELTA3V
A26: 695 | B26: =VLOOKUP($C26,Planilha2!$B:$E,4,FALSE) -> 23598831000102 | C26: 33673 | D26: DELTA3VI
A27: 714 | B27: =VLOOKUP($C27,Planilha2!$B:$E,4,FALSE) -> 23598844000181 | C27: 33680 | D27: DELTA3VII
A28: 354 | B28: =VLOOKUP($C28,Planilha2!$B:$E,4,FALSE) -> 05620523000235 | C28: 29193 | D28: ELDORADOAMPLIACAO
A29: 667 | B29: =VLOOKUP($C29,Planilha2!$B:$E,4,FALSE) -> 330001670001E5 | C29: 27952 | D29: ELETROBOLT
A30: 310200 | B30: =VLOOKUP($C30,Planilha2!$B:$E,4,FALSE) -> 330001670001E5 | C30: 28014 | D30: EUZEBIOROCHA
A31: 113018 | B31: =VLOOKUP($C31,Planilha2!$B:$E,4,FALSE) -> 330001670001E5 | C31: 28014 | D31: EUZEBIOROCHA(ANTIGACUBATAO-CCBS)
... A45: 2197 | B45: =VLOOKUP($C45,Planilha2!$B:$E,4,FALSE) -> 09029666000147 | C45: 29736 | D45: JIRAU-AMPLIACAO
A46: 742 | B46: 3460864000184 | C46: 1304 | D46: LAJEADOI
A47: 2776 | B47: 3460864000184 | C47: 1304 | D47: LAJEADOII
A48: 745 | B48: 3460864000184 | C48: 1304 | D48: LAJEADOIII
A49: 2157 | B49: =VLOOKUP($C49,Planilha2!$B:$E,4,FALSE) -> 15527906000136 | C49: 29717 | D49: LDCBIOENERGIALAGOADAPRATA
A50: 1301 | B50: =VLOOKUP($C50,Planilha2!$B:$E,4,FALSE) -> 15527906000136 | C50: 29718 | D50: LDCBIOENERGIARIOBRILHANTE
A51: 675 | B51: =VLOOKUP($C51,Planilha2!$B:$E,4,FALSE) -> 10472905000118 | C51: 30054 | D51: LINHARES
A52: 310136 | B52: =VLOOKUP($C52,Planilha2!$B:$E,4,FALSE) -> 330001670001E5 | C52: 27975 | D52: LUISCARLOSPRESTES
A53: 113736 | B53: =VLOOKUP($C53,Planilha2!$B:$E,4,FALSE) -> 330001670001E5 | C53: 27975 | D53: LUIZCARLOSPRESTES(ANTIGATRESLAGOAS)
...

Sheet Planilha2
A1: CodCEG | B1: idEmpreendimento | C1: TipoGeracao | D1: NomeEmpreendimento | E1: NumCpfCNPJ | F1: RazaoSocialPj | G1: Participacao | H1: TipoAgente | I1: DtEncerramentoPj | J1: Status | K1: Conforme | L1: ConformeSFG | M1: DescFaseUsina
A2: UFV.RS.MG.047249-2.01 | B2: 47249 | C2: UFV | D2: Alegre II | F2: EDN PROJETOS RENOVÁVEIS E CONSULTORIA LTDA | G2: 100 | H2: PJ | J2: Normal | K2: Sim | L2: Não | M2: Construção não iniciada
A3: UHE.PH.RS.000012-4.01 | B3: 12 | C3: UHE | D3: 14 de Julho | E3: 04237975000199 | F3: COMPANHIA ENERGÉTICA RIO DAS ANTAS | G3: 100 | H3: PJ | J3: Normal | K3: Sim | L3: Sim | M3: Operação
A4: UTE.PE.SC.029920-0.01 | B4: 29920 | C4: UTE | D4: 29 de Outubro | E4: 06538308000171 | F4: Condomínio Residencial 29 de Outubro | G4: 100 | H4: PJ | J4: Normal | K4: Sim | L4: Sim | M4: Operação
A5: UTE.FL.RS.048608-6.01 | B5: 48608 | C5: UTE | D5: 3 Tentos Ijuí | F5: TRÊS TENTOS AGROINDUSTRIAL S.A. | G5: 100 | H5: PJ | J5: Normal | K5: Sim | L5: Sim | M5: Operação
A6: UTE.PE.MG.032686-0.01 | B6: 32686 | C6: UTE | D6: 300KVA SCANIA | E6: 23640204000192 | F6: Mineração Curimbaba Ltda. | G6: 100 | H6: PJ | J6: Normal | K6: Sim | L6: Sim | M6: Operação
A7: UTE.PE.SP.028642-7.01 | B7: 28642 | C7: UTE | D7: 3M Itapetininga | E7: 459853710006E3 | F7: 3M do Brasil Ltda | G7: 100 | H7: PJ | J7: Normal | K7: Sim | L7: Sim | M7: Operação
A8: UTE.PE.SP.028919-1.01 | B8: 28919 | C8: UTE | D8: 3M Sumaré | E8: 459853710006E3 | F8: 3M do Brasil Ltda | G8: 100 | H8: PJ | J8: Normal | K8: Sim | L8: Sim | M8: Operação
A9: PCH.PH.MS.037568-3.01 | B9: 37568 | C9: PCH | D9: A | F9: ENERGÉTICA DAS EMAS LTDA | G9: 100 | H9: PJ | J9: Normal | K9: Sim | L9: Não | M9: Construção não iniciada
A10: UTE.PE.AC.032707-7.01 | B10: 32707 | C10: UTE | D10: A.C.D.A. IMPORTAÇÃO E EXPORTAÇÃO - AMAPÁ | E10: 84308980000184 | F10: A.C.D.A. Importação e exportação Ltda | G10: 100 | H10: PJ | J10: Normal | K10: Sim | L10: Sim | M10: Operação
A11: UTE.PE.AC.032725-5.01 | B11: 32725 | C11: UTE | D11: A.C.D.A. IMPORTAÇÃO E EXPORTAÇÃO - AVIÁRIO | E11: 84308980000184 | F11: A.C.D.A. Importação e exportação Ltda | G11: 100 | H11: PJ | J11: Normal | K11: Sim | L11: Sim | M11: Operação
A12: UTE.PE.AC.032728-0.01 | B12: 32728 | C12: UTE | D12: A.C.D.A. IMPORTAÇÃO E EXPORTAÇÃO - BOSQUE | E12: 84308980000184 | F12: A.C.D.A. Importação e exportação Ltda | G12: 100 | H12: PJ | J12: Normal | K12: Sim | L12: Sim | M12: Operação
A13: UTE.PE.AC.032704-2.01 | B13: 32704 | C13: UTE | D13: A.C.D.A. IMPORTAÇÃO E EXPORTAÇÃO - CHICO MENDES | E13: 84308980000184 | F13: A.C.D.A. Importação e exportação Ltda | G13: 100 | H13: PJ | J13: Normal | K13: Sim | L13: Sim | M13: Operação
A14: UTE.PE.AC.032701-8.01 | B14: 32701 | C14: UTE | D14: A.C.D.A. IMPORTAÇÃO E EXPORTAÇÃO - MIX | E14: 84308980000184 | F14: A.C.D.A. Importação e exportação Ltda | G14: 100 | H14: PJ | J14: Normal | K14: Sim | L14: Sim | M14: Operação
A15: UTE.PE.RO.032731-0.01 | B15: 32731 | C15: UTE | D15: A.C.D.A. IMPORTAÇÃO E EXPORTAÇÃO - PVH | E15: 84308980000184 | F15: A.C.D.A. Importação e exportação Ltda | G15: 100 | H15: PJ | J15: Normal | K15: Sim | L15: Sim | M15: Operação
A16: UTE.PE.AC.032874-0.01 | B16: 32874 | C16: UTE | D16: A.C.D.A. IMPORTAÇÃO E EXPORTAÇÃO - RIO DE JANEIRO | E16: 84308980000184 | F16: A.C.D.A. Importação e exportação Ltda | G16: 100 | H16: PJ | J16: Normal | K16: Sim | L16: Sim | M16: Operação
A17: UTE.PE.AC.032775-1.01 | B17: 32775 | C17: UTE | D17: A.C.D.A. IMPORTAÇÃO E EXPORTAÇÃO - VAREJÃO | E17: 84308980000184 | F17: A.C.D.A. Importação e exportação Ltda | G17: 100 | H17: PJ | J17: Normal | K17: Sim | L17: Sim | M17: Operação
A18: UTE.PE.GO.028991-4.01 | B18: 28991 | C18: UTE | D18: Abatedouro São Salvador | E18: 03387396000160 | F18: SAO SALVADOR ALIMENTOS S/A | G18: 100 | H18: PJ | J18: Normal | K18: Sim | L18: Sim | M18: Operação
A19: CGH.PH.RS.000015-9.01 | B19: 15 | C19: CGH | D19: Abaúna | E19: 11192351000168 | F19: Cooperativa de Geração de Energia e Desenvolvimento | G19: 100 | H19: PJ | J19: Normal | K19: Sim | L19: Sim | M19: Operação
A20: UTE.PE.MG.030905-2.01 | B20: 30905 | C20: UTE | D20: ABC | E20: 041496370002E3 | F20: Adição Distribuição Express Ltda. | G20: 100 | H20: PJ | J20: Normal | K20: Sim | L20: Sim | M20: Operação
A21: UTE.PE.MG.031170-7.01 | B21: 31170 | C21: UTE | D21: ABC | E21: 041496370002E3 | F21: Adição Distribuição Express Ltda. | G21: 100 | H21: PJ | J21: Normal | K21: Sim | L21: Sim | M21: Operação
... A58: UFV.RS.PA.045619-5.01 | B58: 45619 | C58: UFV | D58: Acacio Azevedo de Sousa | E58: 04895728000180 | F58: EQUATORIAL PARÁ DISTRIBUIDORA DE ENERGIA S.A. | G58: 100 | H58: PJ | J58: Normal | K58: Sim | L58: Sim | M58: Operação
A59: UFV.RS.PA.055537-1.01 | B59: 55537 | C59: UFV | D59: Açaí Tapajós | F59: Açaí Tapajós Industria e Comercio Eireli | G59: 100 | H59: PJ | J59: Normal | K59: Sim | L59: Sim | M59: Operação
A60: UFV.RS.PA.055102-3.01 | B60: 55102 | C60: UFV | D60: Acassia Rodrigues Lima | E60: 04895728000180 | F60: EQUATORIAL PARÁ DISTRIBUIDORA DE ENERGIA S.A. | G60: 100 | H60: PJ | J60: Normal | K60: Sim | L60: Sim | M60: Operação
A61: EOL.CV.BA.031433-1.01 | B61: 31433 | C61: EOL | D61: Acauã | E61: 33541368000116 | F61: COMPANHIA HIDRO ELÉTRICA DO SÃO FRANCISCO | G61: 100 | H61: PJ | J61: Normal | K61: Sim | L61: Sim | M61: Operação
A62: UFV.RS.RN.034436-2.01 | B62: 34436 | C62: UFV | D62: Acauã 1 | F62: Acauã Solar Energia SPE Ltda. | G62: 100 | H62: PJ | J62: Normal | K62: Sim | L62: Não | M62: Construção não iniciada
A63: EOL.CV.RN.033597-5.01 | B63: 33597 | C63: EOL | D63: Acauã I | E63: 35842703000141 | F63: CENTRAL EÓLICA ACAUÃ I S.A. | G63: 100 | H63: PJ | J63: Normal | K63: Sim | L63: Sim | M63: Construção
A64: EOL.CV.RN.033598-3.01 | B64: 33598 | C64: EOL | D64: Acauã II | E64: 35842703000141 | F64: CENTRAL EÓLICA ACAUÃ I S.A. | G64: 100 | H64: PJ | J64: Normal | K64: Sim | L64: Sim | M64: Construção
A65: EOL.CV.RN.033864-8.01 | B65: 33864 | C65: EOL | D65: Acauã III | E65: 35842711000198 | F65: CENTRAL EÓLICA ACAUÃ III S.A. | G65: 100 | H65: PJ | J65: Normal | K65: Sim | L65: Sim | M65: Construção
A66: UTE.PE.AC.030904-4.01 | B66: 30904 | C66: UTE | D66: ACDA | E66: 84308980000184 | F66: A.C.D.A. Importação e exportação Ltda | G66: 100 | H66: PJ | J66: Normal | K66: Sim | L66: Sim | M66: Operação
A67: CGH.PH.SC.030419-0.01 | B67: 30419 | C67: CGH | D67: Acearia Frederico Missner (Antiga Rio Luiz Alves) | E67: 82719956000102 | F67: Acearia Frederico Missner S.A | G67: 100 | H67: PJ | J67: Normal | K67: Sim | L67: Sim | M67: Operação
A68: UFV.RS.PA.042942-2.01 | B68: 42942 | C68: UFV | D68: Aceel Gil de Freitas | E68: 04895728000180 | F68: EQUATORIAL PARÁ DISTRIBUIDORA DE ENERGIA S.A. | G68: 100 | H68: PJ | J68: Normal | K68: Sim | L68: Sim | M68: Operação
A69: UFV.RS.PA.039798-9.01 | B69: 39798 | C69: UFV | D69: Acenildo Castro de Lima | E69: 04895728000180 | F69: EQUATORIAL PARÁ DISTRIBUIDORA DE ENERGIA S.A. | G69: 100 | H69: PJ | J69: Normal | K69: Sim | L69: Sim | M69: Operação
A70: UFV.RS.PA.042943-0.01 | B70: 42943 | C70: UFV | D70: Acivaldo Souza Peixoto | E70: 04895728000180 | F70: EQUATORIAL PARÁ DISTRIBUIDORA DE ENERGIA S.A. | G70: 100 | H70: PJ | J70: Normal | K70: Sim | L70: Sim | M70: Operação
A71: UTE.CM.MG.000019-1.01 | B71: 19 | C71: UTE | D71: Açominas | E71: 172274220001E4 | F71: GERDAU AÇOMINAS S/A | G71: 100 | H71: PJ | J71: Normal | K71: Sim | L71: Sim | M71: Operação
A72: PCH.PH.PR.035550-0.01 | B72: 35550 | C72: PCH | D72: Açungui 2E | E72: 81172264000124 | F72: TRANSLEAD EMPREENDIMENTOS E INCORPORAÇÕES LTDA | G72: 100 | H72: PJ | J72: Normal | K72: Sim | L72: Não | M72: Construção não iniciada
A73: PCH.PH.PR.036917-9.01 | B73: 36917 | C73: PCH | D73: Açungui 2F | E73: 81172264000124 | F73: TRANSLEAD EMPREENDIMENTOS E INCORPORAÇÕES LTDA | G73: 100 | H73: PJ | J73: Normal | K73: Sim | L73: Não | M73: Construção não iniciada
A74: UFV.RS.PA.061365-7.01 | B74: 61365 | C74: UFV | D74: Ada Alves da Conseicao | E74: 04895728000180 | F74: EQUATORIAL PARÁ DISTRIBUIDORA DE ENERGIA S.A. | G74: 100 | H74: PJ | J74: Normal | K74: Sim | L74: Sim | M74: Operação
... A253: UFV.RS.PA.039134-4.01 | B253: 39134 | C253: UFV | D253: Aduzinda Abreu Dias | E253: 04895728000180 | F253: EQUATORIAL PARÁ DISTRIBUIDORA DE ENERGIA S.A. | G253: 100 | H253: PJ | J253: Normal | K253: Sim | L253: Sim | M253: Operação
A254: UTE.PE.RS.029380-6.01 | B254: 29380 | C254: UTE | D254: Aeroporto de Bagé | G254: 100 | K254: Sim | L254: Sim | M254: Operação
...
